<robot name="vss">
    <link name="body">
        <inertial>
            <mass value="0.150"/>
        </inertial>
        <visual>
            <geometry>
                <box size="0.08 0.08 0.054"/>
            </geometry>
        </visual>
        <collision>
            <geometry>
                <box size="0.08 0.08 0.054"/>
            </geometry>
        </collision>
    </link>

    <link name="leftWheel">
        <inertial>
            <mass value="0.015"/>
        </inertial>
        <visual>
            <geometry>
                <cylinder radius="0.026" length="0.0025"/>
            </geometry>
        </visual>
        <collision>
            <geometry>
                <sphere radius="0.026"/>
            </geometry>
        </collision>
    </link>

    <link name="rightWheel">
        <inertial>
            <mass value="0.015"/>
        </inertial>
        <visual>
            <geometry>
                <cylinder radius="0.026" length="0.0025"/>
            </geometry>
        </visual>
        <collision>
            <geometry>
                <sphere radius="0.026"/>
            </geometry>
        </collision>
    </link>

    <joint name="body_leftWheel" type="continuous">
        <origin xyz="0.0 0.03875 -0.002" rpy="-1.570796 0.0 0.0" />
        <axis xyz="0.0 0.0 1.0"/>
        <parent link="body" />
        <child link="leftWheel" />
        <limit effort="0.075" velocity="68.0"/>
    </joint>

    <joint name="body_rightWheel" type="continuous">
        <origin xyz="0.0 -0.03875 -0.002" rpy="-1.570796 0.0 0.0"/>
        <axis xyz="0.0 0.0 1.0"/>
        <parent link="body" />
        <child link="rightWheel" />
        <limit effort="0.075" velocity="68.0"/>
    </joint>

</robot>